Workbook

Sheet Comparação
A1: SKU | B1: Nosso produto | C1: No site? | D1: Preço OMG hoje (R$) | E1: Situação | F1: Produto oficial | G1: Variante | H1: Preço oficial (US$) | I1: Preço cheio (US$) | J1: Disponível lá? | K1: Link oficial | L1: Mercadoria sugerida (R$) | M1: Diferença vs hoje | N1: Observação
A2: MB000945 | B2: Azelaic Acid 10 Ampoule: ampola com 10% de ácido azelaico · 30ml | C2: Sim | D2: 147.9 | E2: Certeiro | F2: Azelaic Acid 10 Ampoule | G2: 30ml | H2: 21.6 | I2: 24 | J2: Sim | K2: https://skin1004.com/products/azelaic-acid-10-ampoule?variant=50120133279990 | L2: =ROUND(H2*(1+Parâmetros!$B$2)*Parâmetros!$B$1,2) | M2: =IF(OR(D2="",L2=""),"",D2/L2-1)
A3: MB000946 | B3: Azelaic Acid 10 Ampoule: ampola com 10% de ácido azelaico · 9ml | C3: Sim | D3: 72.9 | E3: Certeiro | F3: Azelaic Acid 10 Ampoule | G3: 9ml | H3: 10 | J3: Sim | K3: https://skin1004.com/products/azelaic-acid-10-ampoule?variant=50752936378614 | L3: =ROUND(H3*(1+Parâmetros!$B$2)*Parâmetros!$B$1,2) | M3: =IF(OR(D3="",L3=""),"",D3/L3-1)
A4: MB000943 | B4: Azelaic Acid Glass Skin Set: ácido azelaico + discos + creme + protetor | C4: Sim | D4: 436.9 | E4: Certeiro | F4: Azelaic Acid Glass Skin Essential Set | H4: 60 | I4: 75 | J4: Sim | K4: https://skin1004.com/products/azelaic-acid-glass-skin-essential-set-1 | L4: =ROUND(H4*(1+Parâmetros!$B$2)*Parâmetros!$B$1,2) | M4: =IF(OR(D4="",L4=""),"",D4/L4-1)
A5: MB000937 | B5: Centella Ampoule Foam: espuma de limpeza de centella pH 5 · 125ml | C5: Sim | D5: 86.9 | E5: Certeiro | F5: Centella Ampoule Foam | G5: 125ml | H5: 12.6 | I5: 14 | J5: Sim | K5: https://skin1004.com/products/skin1004-madagascar-centella-ampoule-foam?variant=40788189511837 | L5: =ROUND(H5*(1+Parâmetros!$B$2)*Parâmetros!$B$1,2) | M5: =IF(OR(D5="",L5=""),"",D5/L5-1)
A6: MB000936 | B6: Centella Ampoule Foam: espuma de limpeza de centella pH 5 · 20ml | C6: Sim | D6: 28.9 | E6: Certeiro | F6: Centella Ampoule Foam | G6: 20ml | H6: 4 | J6: Sim | K6: https://skin1004.com/products/skin1004-madagascar-centella-ampoule-foam?variant=40788189479069 | L6: =ROUND(H6*(1+Parâmetros!$B$2)*Parâmetros!$B$1,2) | M6: =IF(OR(D6="",L6=""),"",D6/L6-1)
A7: MB000940 | B7: Centella Ampoule: ampola calmante de centella de Madagascar · 30ml | C7: Sim | D7: 68.9 | E7: Certeiro | F7: Centella Ampoule | G7: 30ml | H7: 9.5 | J7: Sim | K7: https://skin1004.com/products/skin1004-madagascar-centella-ampoule?variant=40788189708445 | L7: =ROUND(H7*(1+Parâmetros!$B$2)*Parâmetros!$B$1,2) | M7: =IF(OR(D7="",L7=""),"",D7/L7-1)
A8: MB000939 | B8: Centella Ampoule: ampola calmante de centella de Madagascar · 55ml | C8: Sim | D8: 104.9 | E8: Certeiro | F8: Centella Ampoule | G8: 55ml | H8: 13.5 | I8: 15 | J8: Sim | K8: https://skin1004.com/products/skin1004-madagascar-centella-ampoule?variant=40788189741213 | L8: =ROUND(H8*(1+Parâmetros!$B$2)*Parâmetros!$B$1,2) | M8: =IF(OR(D8="",L8=""),"",D8/L8-1)
A9: MB000932 | B9: Centella Light Cleansing Oil: óleo de limpeza leve com centella · 200ml | C9: Sim | D9: 110.9 | E9: Certeiro | F9: Centella Light Cleansing Oil | G9: 200ml | H9: 18.9 | I9: 21 | J9: Sim | K9: https://skin1004.com/products/skin1004-madagascar-centella-light-cleansing-oil?variant=40788189413533 | L9: =ROUND(H9*(1+Parâmetros!$B$2)*Parâmetros!$B$1,2) | M9: =IF(OR(D9="",L9=""),"",D9/L9-1)
A10: MB000931 | B10: Centella Light Cleansing Oil: óleo de limpeza leve com centella · 30ml | C10: Sim | D10: 39.9 | E10: Certeiro | F10: Centella Light Cleansing Oil | G10: 30ml | H10: 5.5 | J10: Sim | K10: https://skin1004.com/products/skin1004-madagascar-centella-light-cleansing-oil?variant=40788189380765 | L10: =ROUND(H10*(1+Parâmetros!$B$2)*Parâmetros!$B$1,2) | M10: =IF(OR(D10="",L10=""),"",D10/L10-1)
A11: MB000930 | B11: Centella Quick Calming Pad: discos calmantes de centella 70 unidades | C11: Sim | D11: 136.9 | E11: Certeiro | F11: Centella Quick Calming Pad | G11: 70 Pads | H11: 18.9 | I11: 21 | J11: Sim | K11: https://skin1004.com/products/skin1004-madagascar-centella-quick-calming-pad | L11: =ROUND(H11*(1+Parâmetros!$B$2)*Parâmetros!$B$1,2) | M11: =IF(OR(D11="",L11=""),"",D11/L11-1)
A12: MB000928 | B12: Centella Soothing Cream: gel-creme calmante de centella com ceramidas · 75ml | C12: Sim | D12: 110.9 | E12: Certeiro | F12: Centella Soothing Cream | G12: 75ml | H12: 14.4 | I12: 16 | J12: Sim | K12: https://skin1004.com/products/skin1004-madagascar-centella-soothing-cream?variant=40788189839517 | L12: =ROUND(H12*(1+Parâmetros!$B$2)*Parâmetros!$B$1,2) | M12: =IF(OR(D12="",L12=""),"",D12/L12-1)
A13: MB003029 | B13: Centella Teca Ampoule: ampola concentrada de centella com TECA e PDRN 50 ml | C13: Sim | D13: 110.9 | E13: Certeiro | F13: Centella Teca Ampoule | G13: 50ml | H13: 15.3 | I13: 17 | J13: Sim | K13: https://skin1004.com/products/centella-teca-ampoule | L13: =ROUND(H13*(1+Parâmetros!$B$2)*Parâmetros!$B$1,2) | M13: =IF(OR(D13="",L13=""),"",D13/L13-1)
A14: MB003028 | B14: Centella Teca Cream: gel-creme de centella com TECA e PDRN 75 ml | C14: Sim | D14: 130.9 | E14: Certeiro | F14: Centella Teca Cream | G14: 75ml | H14: 18 | I14: 20 | J14: Sim | K14: https://skin1004.com/products/centella-teca-cream | L14: =ROUND(H14*(1+Parâmetros!$B$2)*Parâmetros!$B$1,2) | M14: =IF(OR(D14="",L14=""),"",D14/L14-1)
A15: MB000924 | B15: Centella Teca Intensive Soothing Routine Set: rotina TECA + protetor solar | C15: Sim | D15: 442.9 | E15: Certeiro | F15: Centella Teca Intensive Soothing Routine Set | H15: 60.8 | I15: 76 | J15: Sim | K15: https://skin1004.com/products/centella-teca-intensive-soothing-routine-set | L15: =ROUND(H15*(1+Parâmetros!$B$2)*Parâmetros!$B$1,2) | M15: =IF(OR(D15="",L15=""),"",D15/L15-1)
A16: MB000921 | B16: Centella Teca Soothing Toner: tônico calmante com TECA e LHA 210 ml | C16: Sim | D16: 130.9 | E16: Certeiro | F16: Centella Teca Soothing Toner | G16: 210ml | H16: 18 | I16: 20 | J16: Sim | K16: https://skin1004.com/products/centella-teca-soothing-toner | L16: =ROUND(H16*(1+Parâmetros!$B$2)*Parâmetros!$B$1,2) | M16: =IF(OR(D16="",L16=""),"",D16/L16-1)
A17: MB000919 | B17: Centella Toning Toner: tônico de centella com PHA para uso diário · 210ml | C17: Sim | D17: 117.9 | E17: Certeiro | F17: Centella Toning Toner | G17: 210ml | H17: 16.2 | I17: 18 | J17: Sim | K17: https://skin1004.com/products/skin1004-madagascar-centella-toning-toner?variant=40788189610141 | L17: =ROUND(H17*(1+Parâmetros!$B$2)*Parâmetros!$B$1,2) | M17: =IF(OR(D17="",L17=""),"",D17/L17-1)
A18: MB000918 | B18: Centella Toning Toner: tônico de centella com PHA para uso diário · 30ml | C18: Sim | D18: 35.9 | E18: Certeiro | F18: Centella Toning Toner | G18: 30ml | H18: 5 | J18: Sim | K18: https://skin1004.com/products/skin1004-madagascar-centella-toning-toner?variant=40788189577373 | L18: =ROUND(H18*(1+Parâmetros!$B$2)*Parâmetros!$B$1,2) | M18: =IF(OR(D18="",L18=""),"",D18/L18-1)
A19: MB000920 | B19: Centella Toning Toner: tônico de centella com PHA para uso diário · 400ml | C19: Sim | D19: 169.9 | E19: Certeiro | F19: Centella Toning Toner | G19: 400ml | H19: 23.4 | I19: 26 | J19: Sim | K19: https://skin1004.com/products/skin1004-madagascar-centella-toning-toner?variant=40788189642909 | L19: =ROUND(H19*(1+Parâmetros!$B$2)*Parâmetros!$B$1,2) | M19: =IF(OR(D19="",L19=""),"",D19/L19-1)
A20: MB000915 | B20: Centella Watergel Sheet Ampoule Mask: máscara em folha de centella 25 ml · 25ml | C20: Sim | D20: 20.9 | E20: Certeiro | F20: Centella Watergel Sheet Ampoule Mask | G20: 25ml | H20: 3 | J20: Sim | K20: https://skin1004.com/products/skin1004-madagascar-centella-watergel-sheet-ampoule-mask?variant=40788190003357 | L20: =ROUND(H20*(1+Parâmetros!$B$2)*Parâmetros!$B$1,2) | M20: =IF(OR(D20="",L20=""),"",D20/L20-1)
A21: MB000916 | B21: Centella Watergel Sheet Ampoule Mask: máscara em folha de centella 25 ml · 25ml x 5EA | C21: Sim | D21: 97.9 | E21: Certeiro | F21: Centella Watergel Sheet Ampoule Mask | G21: 25ml x 5EA | H21: 13.5 | I21: 15 | J21: Sim | K21: https://skin1004.com/products/skin1004-madagascar-centella-watergel-sheet-ampoule-mask?variant=40788190036125 | L21: =ROUND(H21*(1+Parâmetros!$B$2)*Parâmetros!$B$1,2) | M21: =IF(OR(D21="",L21=""),"",D21/L21-1)
A22: MB000913 | B22: Daily Moisture Routine Duo: creme Hyalu-Cica + sérum solar Water-Fit FPS 50 | C22: Sim | D22: 232.9 | E22: Certeiro | F22: Daily Moisture Routine Duo | H22: 32 | I22: 40 | J22: Sim | K22: https://skin1004.com/products/daily-moisture-routine-duo | L22: =ROUND(H22*(1+Parâmetros!$B$2)*Parâmetros!$B$1,2) | M22: =IF(OR(D22="",L22=""),"",D22/L22-1)
A23: MB000912 | B23: Double Cleansing Duo: óleo de limpeza + espuma de centella | C23: Sim | D23: 203.9 | E23: Certeiro | F23: Double Cleansing Duo | H23: 28 | I23: 35 | J23: Sim | K23: https://skin1004.com/products/double-cleansing-duo-1 | L23: =ROUND(H23*(1+Parâmetros!$B$2)*Parâmetros!$B$1,2) | M23: =IF(OR(D23="",L23=""),"",D23/L23-1)
A24: MB000910 | B24: Hyalu-Cica Blue Serum: sérum hidratante com ácido hialurônico e centella | C24: Sim | D24: 101.9 | E24: Certeiro | F24: Hyalu-Cica Blue Serum | G24: 30ml | H24: 14 | J24: Sim | K24: https://skin1004.com/products/skin1004-madagascar-centella-hyalu-cica-blue-serum?variant=40788190396573 | L24: =ROUND(H24*(1+Parâmetros!$B$2)*Parâmetros!$B$1,2) | M24: =IF(OR(D24="",L24=""),"",D24/L24-1)
A25: MB000909 | B25: Hyalu-Cica Brightening Toner: tônico hidratante e iluminador com AHA e LHA · 210ml | C25: Sim | D25: 130.9 | E25: Certeiro | F25: Hyalu-Cica Brightening Toner | G25: 210ml | H25: 18 | I25: 20 | J25: Sim | K25: https://skin1004.com/products/skin1004-madagascar-centella-hyalu-cica-brightening-toner?variant=40788190331037 | L25: =ROUND(H25*(1+Parâmetros!$B$2)*Parâmetros!$B$1,2) | M25: =IF(OR(D25="",L25=""),"",D25/L25-1)
A26: MB000908 | B26: Hyalu-Cica Brightening Toner: tônico hidratante e iluminador com AHA e LHA · 30ml | C26: Sim | D26: 42.9 | E26: Certeiro | F26: Hyalu-Cica Brightening Toner | G26: 30ml | H26: 6 | J26: Sim | K26: https://skin1004.com/products/skin1004-madagascar-centella-hyalu-cica-brightening-toner?variant=40788190298269 | L26: =ROUND(H26*(1+Parâmetros!$B$2)*Parâmetros!$B$1,2) | M26: =IF(OR(D26="",L26=""),"",D26/L26-1)
A27: MB000906 | B27: Hyalu-Cica First Ampoule: ampola hidratante de primeiro passo · 100ml | C27: Sim | D27: 150.9 | E27: Certeiro | F27: Hyalu-Cica First Ampoule | G27: 100ml | H27: 20.7 | I27: 23 | J27: Sim | K27: https://skin1004.com/products/skin1004-madagascar-centella-hyalu-cica-first-ampoule?variant=45493248458998 | L27: =ROUND(H27*(1+Parâmetros!$B$2)*Parâmetros!$B$1,2) | M27: =IF(OR(D27="",L27=""),"",D27/L27-1)
A28: MB000907 | B28: Hyalu-Cica First Ampoule: ampola hidratante de primeiro passo · 50ml | C28: Sim | D28: 107.9 | E28: Certeiro | F28: Hyalu-Cica First Ampoule | G28: 50ml | H28: 14.85 | I28: 16.5 | J28: Sim | K28: https://skin1004.com/products/skin1004-madagascar-centella-hyalu-cica-first-ampoule?variant=45493248491766 | L28: =ROUND(H28*(1+Parâmetros!$B$2)*Parâmetros!$B$1,2) | M28: =IF(OR(D28="",L28=""),"",D28/L28-1)
A29: MB000903 | B29: Hyalu-Cica Hydrating Mask: máscara em folha com 8 ácidos hialurônicos 23 ml · 23ml | C29: Sim | D29: 20.9 | E29: Certeiro | F29: Hyalu-Cica Hydrating Mask | G29: 23ml | H29: 3 | J29: Sim | K29: https://skin1004.com/products/hyalu-cica-hydrating-mask?variant=49826893234422 | L29: =ROUND(H29*(1+Parâmetros!$B$2)*Parâmetros!$B$1,2) | M29: =IF(OR(D29="",L29=""),"",D29/L29-1)
A30: MB000904 | B30: Hyalu-Cica Hydrating Mask: máscara em folha com 8 ácidos hialurônicos 23 ml · 23ml x 5ea | C30: Sim | D30: 97.9 | E30: Certeiro | F30: Hyalu-Cica Hydrating Mask | G30: 23ml x 5ea | H30: 13.5 | I30: 15 | J30: Sim | K30: https://skin1004.com/products/hyalu-cica-hydrating-mask?variant=49826893267190 | L30: =ROUND(H30*(1+Parâmetros!$B$2)*Parâmetros!$B$1,2) | M30: =IF(OR(D30="",L30=""),"",D30/L30-1)
A31: MB000902 | B31: Hyalu-Cica Jelly-Fit Ampoule Pad: discos em gel com ácido hialurônico 60 unidades | C31: Sim | D31: 136.9 | E31: Certeiro | F31: Hyalu-Cica Jelly-Fit Ampoule Pad | G31: 60ea | H31: 18.9 | I31: 21 | J31: Sim | K31: https://skin1004.com/products/hyalu-cica-jelly-fit-ampoule-pad | L31: =ROUND(H31*(1+Parâmetros!$B$2)*Parâmetros!$B$1,2) | M31: =IF(OR(D31="",L31=""),"",D31/L31-1)
A32: MB000901 | B32: Hyalu-Cica Moisture Cream: creme hidratante com ácido hialurônico e colágeno · 30ml | C32: Sim | D32: 64.9 | E32: Certeiro | F32: Hyalu-Cica Moisture Cream | G32: 30ml | H32: 9 | J32: Sim | K32: https://skin1004.com/products/madagascar-centella-hyalu-cica-moisture-cream-75ml?variant=50111823872246 | L32: =ROUND(H32*(1+Parâmetros!$B$2)*Parâmetros!$B$1,2) | M32: =IF(OR(D32="",L32=""),"",D32/L32-1)
A33: MB000900 | B33: Hyalu-Cica Moisture Cream: creme hidratante com ácido hialurônico e colágeno · 75ml | C33: Sim | D33: 136.9 | E33: Certeiro | F33: Hyalu-Cica Moisture Cream | G33: 75ml | H33: 18.9 | I33: 21 | J33: Sim | K33: https://skin1004.com/products/madagascar-centella-hyalu-cica-moisture-cream-75ml?variant=50098851283190 | L33: =ROUND(H33*(1+Parâmetros!$B$2)*Parâmetros!$B$1,2) | M33: =IF(OR(D33="",L33=""),"",D33/L33-1)
A34: MB000897 | B34: Hyalu-Cica Sleeping Pack: máscara noturna em gel com ácido hialurônico | C34: Sim | D34: 50.9 | E34: Certeiro | F34: Hyalu-Cica Sleeping Pack | G34: 30ml | H34: 7 | J34: Sim | K34: https://skin1004.com/products/skin1004-madagascar-centella-hyalu-cica-sleeping-pack?variant=40788190462109 | L34: =ROUND(H34*(1+Parâmetros!$B$2)*Parâmetros!$B$1,2) | M34: =IF(OR(D34="",L34=""),"",D34/L34-1)
A35: MB000895 | B35: Hyalu-Cica Travel Kit: rotina hidratante em 4 minis de 30 ml | C35: Sim | D35: 160.9 | E35: Certeiro | F35: Hyalu-Cica Travel Kit | G35: 4-piece Kit | H35: 22.1 | I35: 26 | J35: Sim | K35: https://skin1004.com/products/hyalu-cica-travel-kit | L35: =ROUND(H35*(1+Parâmetros!$B$2)*Parâmetros!$B$1,2) | M35: =IF(OR(D35="",L35=""),"",D35/L35-1)
A36: MB000889 | B36: Hyalu-Cica Water-Fit Sun Serum UV: sérum protetor solar FPS 50 amplo espectro · 50ml | C36: Sim | D36: 123.9 | E36: Certeiro | F36: Hyalu-Cica Water-Fit Sun Serum UV | G36: 50ml | H36: 17.1 | I36: 19 | J36: Sim | K36: https://skin1004.com/products/hyalu-cica-water-fit-sun-serum-uv?variant=49278926487798 | L36: =ROUND(H36*(1+Parâmetros!$B$2)*Parâmetros!$B$1,2) | M36: =IF(OR(D36="",L36=""),"",D36/L36-1)
A37: MB000890 | B37: Hyalu-Cica Water-Fit Sun Serum UV: sérum protetor solar FPS 50 amplo espectro · Twin Pack (50ml x 2) | C37: Sim | D37: 166.9 | E37: Certeiro | F37: Hyalu-Cica Water-Fit Sun Serum UV | G37: Twin Pack (50ml x 2) | H37: 24.3 | I37: 27 | J37: Sim | K37: https://skin1004.com/products/hyalu-cica-water-fit-sun-serum-uv?variant=51261874995446 | L37: =ROUND(H37*(1+Parâmetros!$B$2)*Parâmetros!$B$1,2) | M37: =IF(OR(D37="",L37=""),"",D37/L37-1)
A38: MB000888 | B38: Hyalu-Teca Firming Cream: creme firmador com ácido hialurônico e TECA 50 ml | C38: Sim | D38: 136.9 | E38: Certeiro | F38: Hyalu-Teca Firming Cream | G38: 50ml | H38: 18.9 | I38: 21 | J38: Sim | K38: https://skin1004.com/products/hyalu-teca-firming-cream | L38: =ROUND(H38*(1+Parâmetros!$B$2)*Parâmetros!$B$1,2) | M38: =IF(OR(D38="",L38=""),"",D38/L38-1)
A39: MB000887 | B39: Hyalu-Teca Glass Skin Milk: essência leitosa hidratante e iluminadora 210 ml | C39: Sim | D39: 143.9 | E39: Certeiro | F39: Hyalu-Teca Glass Skin Milk | G39: 210ml | H39: 19.8 | I39: 22 | J39: Sim | K39: https://skin1004.com/products/hyalu-teca-glass-skin-milk | L39: =ROUND(H39*(1+Parâmetros!$B$2)*Parâmetros!$B$1,2) | M39: =IF(OR(D39="",L39=""),"",D39/L39-1)
A40: MB000886 | B40: Hyalu-Teca Moisture Glow Ritual Set: ampola + essência leitosa + creme | C40: Sim | D40: 360.9 | E40: Certeiro | F40: Hyalu-Teca Moisture Glow Ritual Set | H40: 49.6 | I40: 62 | J40: Sim | K40: https://skin1004.com/products/hyalu-teca-moisture-glow-ritual-set | L40: =ROUND(H40*(1+Parâmetros!$B$2)*Parâmetros!$B$1,2) | M40: =IF(OR(D40="",L40=""),"",D40/L40-1)
...

Sheet Catálogo oficial
A1: Produto oficial | B1: Variante | C1: Preço (US$) | D1: Preço cheio (US$) | E1: Disponível? | F1: Kit/combo? | G1: SKU deles | H1: Link
A2: 1004Day Edition - Bojagi(2026) | C2: 12 | E2: Sim | G2: KRSKY018 | H2: https://skin1004.com/products/1004day-edition-bojagi-2026
A3: 1004Day Edition - Pouch Keyring(2026) | C3: 12 | E3: Sim | G3: KRSKY019 | H3: https://skin1004.com/products/1004day-edition-pouch-keyring2026
A4: Azelaic Acid 10 Ampoule | B4: 30ml | C4: 21.6 | D4: 24 | E4: Sim | G4: EXSKA001 | H4: https://skin1004.com/products/azelaic-acid-10-ampoule?variant=50120133279990
A5: Azelaic Acid 10 Ampoule | B5: 9ml | C5: 10 | E5: Sim | G5: EXSKA002 | H5: https://skin1004.com/products/azelaic-acid-10-ampoule?variant=50752936378614
A6: Azelaic Acid Glass Skin Essential Set | C6: 60 | D6: 75 | E6: Sim | F6: Sim | H6: https://skin1004.com/products/azelaic-acid-glass-skin-essential-set-1
A7: Centella Ampoule Foam | B7: 125ml | C7: 12.6 | D7: 14 | E7: Sim | G7: USSKL011 | H7: https://skin1004.com/products/skin1004-madagascar-centella-ampoule-foam?variant=40788189511837
A8: Centella Ampoule Foam | B8: 20ml | C8: 4 | E8: Sim | G8: USSKL006 | H8: https://skin1004.com/products/skin1004-madagascar-centella-ampoule-foam?variant=40788189479069
A9: Centella Ampoule Kit | B9: 4-piece Kit | C9: 23.8 | D9: 28 | E9: Sim | F9: Sim | G9: USSKK009 | H9: https://skin1004.com/products/centella-ampoule-kit
A10: Centella Ampoule | B10: 100ml | C10: 19.8 | D10: 22 | E10: Sim | G10: USSKA022 | H10: https://skin1004.com/products/skin1004-madagascar-centella-ampoule?variant=40788189773981
A11: Centella Ampoule | B11: 30ml | C11: 9.5 | E11: Sim | G11: USSKA012 | H11: https://skin1004.com/products/skin1004-madagascar-centella-ampoule?variant=40788189708445
A12: Centella Ampoule | B12: 55ml | C12: 13.5 | D12: 15 | E12: Sim | G12: USSKA023 | H12: https://skin1004.com/products/skin1004-madagascar-centella-ampoule?variant=40788189741213
A13: Centella Cream | B13: 30ml | C13: 9 | E13: Esgotado | G13: USSKC011 | H13: https://skin1004.com/products/skin1004-madagascar-centella-cream?variant=40788189872285
A14: Centella Cream | B14: 75ml | C14: 18 | D14: 20 | E14: Sim | G14: USSKC016 | H14: https://skin1004.com/products/skin1004-madagascar-centella-cream?variant=40788189905053
A15: Centella Light Cleansing Oil | B15: 200ml | C15: 18.9 | D15: 21 | E15: Sim | G15: USSKL009 | H15: https://skin1004.com/products/skin1004-madagascar-centella-light-cleansing-oil?variant=40788189413533
A16: Centella Light Cleansing Oil | B16: 30ml | C16: 5.5 | E16: Sim | G16: USSKL004 | H16: https://skin1004.com/products/skin1004-madagascar-centella-light-cleansing-oil?variant=40788189380765
A17: Centella Quick Calming Pad | B17: 70 Pads | C17: 18.9 | D17: 21 | E17: Sim | G17: USSKM009 | H17: https://skin1004.com/products/skin1004-madagascar-centella-quick-calming-pad
A18: Centella Skincare Routine Set | C18: 73.6 | D18: 92 | E18: Sim | F18: Sim | G18: CRS001 | H18: https://skin1004.com/products/centella-skincare-routine-set-1
A19: Centella Soothing Cream | B19: 30ml | C19: 7.5 | E19: Sim | G19: USSKC009 | H19: https://skin1004.com/products/skin1004-madagascar-centella-soothing-cream?variant=40788189806749
A20: Centella Soothing Cream | B20: 75ml | C20: 14.4 | D20: 16 | E20: Sim | G20: USSKC015 | H20: https://skin1004.com/products/skin1004-madagascar-centella-soothing-cream?variant=40788189839517
A21: Centella Teca Ampoule | B21: 50ml | C21: 15.3 | D21: 17 | E21: Sim | G21: USSKA060 | H21: https://skin1004.com/products/centella-teca-ampoule
A22: Centella Teca Cream | B22: 75ml | C22: 18 | D22: 20 | E22: Sim | G22: USSKC038 | H22: https://skin1004.com/products/centella-teca-cream
A23: Centella Teca Intensive Soothing Routine Set | C23: 60.8 | D23: 76 | E23: Sim | F23: Sim | H23: https://skin1004.com/products/centella-teca-intensive-soothing-routine-set
A24: Centella Teca Soothing Toner | B24: 210ml | C24: 18 | D24: 20 | E24: Sim | G24: USSKT022 | H24: https://skin1004.com/products/centella-teca-soothing-toner
A25: Centella Toning Toner | B25: 210ml | C25: 16.2 | D25: 18 | E25: Sim | G25: USSKT007 | H25: https://skin1004.com/products/skin1004-madagascar-centella-toning-toner?variant=40788189610141
A26: Centella Toning Toner | B26: 30ml | C26: 5 | E26: Sim | G26: USSKT005 | H26: https://skin1004.com/products/skin1004-madagascar-centella-toning-toner?variant=40788189577373
A27: Centella Toning Toner | B27: 400ml | C27: 23.4 | D27: 26 | E27: Sim | G27: USSKT008 | H27: https://skin1004.com/products/skin1004-madagascar-centella-toning-toner?variant=40788189642909
A28: Centella Travel Kit | B28: 5-piece Kit | C28: 22.1 | D28: 26 | E28: Sim | F28: Sim | G28: USSKK011 | H28: https://skin1004.com/products/skin1004-madagascar-centella-travel-kit
A29: Centella Watergel Sheet Ampoule Mask | B29: 25ml | C29: 3 | E29: Sim | G29: USSKM007 | H29: https://skin1004.com/products/skin1004-madagascar-centella-watergel-sheet-ampoule-mask?variant=40788190003357
A30: Centella Watergel Sheet Ampoule Mask | B30: 25ml x 5EA | C30: 13.5 | D30: 15 | E30: Sim | G30: USSKM008 | H30: https://skin1004.com/products/skin1004-madagascar-centella-watergel-sheet-ampoule-mask?variant=40788190036125
A31: Daily Moisture Routine Duo | C31: 32 | D31: 40 | E31: Sim | F31: Sim | H31: https://skin1004.com/products/daily-moisture-routine-duo
A32: Double Cleansing Duo | C32: 28 | D32: 35 | E32: Sim | F32: Sim | H32: https://skin1004.com/products/double-cleansing-duo-1
A33: Hudson's GURWM Set | C33: 115.2 | D33: 144 | E33: Sim | F33: Sim | H33: https://skin1004.com/products/hudsons-gurwm-set
A34: Hudson’s GRWM Set | C34: 68.8 | D34: 86 | E34: Sim | F34: Sim | H34: https://skin1004.com/products/hudsons-grwm-set
A35: Hyalu-Cica Blue Serum | B35: 30ml | C35: 14 | E35: Sim | G35: USSKA017 | H35: https://skin1004.com/products/skin1004-madagascar-centella-hyalu-cica-blue-serum?variant=40788190396573
A36: Hyalu-Cica Blue Serum | B36: 50ml | C36: 19.8 | D36: 22 | E36: Sim | G36: USSKA034 | H36: https://skin1004.com/products/skin1004-madagascar-centella-hyalu-cica-blue-serum?variant=40788190429341
A37: Hyalu-Cica Brightening Toner | B37: 210ml | C37: 18 | D37: 20 | E37: Sim | G37: USSKT013 | H37: https://skin1004.com/products/skin1004-madagascar-centella-hyalu-cica-brightening-toner?variant=40788190331037
A38: Hyalu-Cica Brightening Toner | B38: 30ml | C38: 6 | E38: Sim | G38: USSKT006 | H38: https://skin1004.com/products/skin1004-madagascar-centella-hyalu-cica-brightening-toner?variant=40788190298269
A39: Hyalu-Cica Cloudy Mist | B39: 120ml | C39: 19.8 | D39: 22 | E39: Sim | G39: USSKT002 | H39: https://skin1004.com/products/skin1004-madagascar-centella-hyalu-cica-cloudy-mist
A40: Hyalu-Cica First Ampoule | B40: 100ml | C40: 20.7 | D40: 23 | E40: Sim | G40: USSKA035 | H40: https://skin1004.com/products/skin1004-madagascar-centella-hyalu-cica-first-ampoule?variant=45493248458998
...

Sheet Parâmetros
A1: Câmbio US$ → R$ | B1: 5.4
A2: Acréscimo sobre o preço do exterior | B2: 0.2
A4: Mude os valores acima e a coluna "Mercadoria sugerida" recalcula.
A5: Site oficial: https://skin1004.com · loja "SKIN1004" · moeda USD · lido em 30/10/2026 06:07 UTC
A6: Regra (Guia de precificação OMG): produto sem concorrente válido → varejo no exterior em US$ + 20%, convertido = preço da mercadoria no site. Frete e impostos entram no checkout.
